Workbook

Sheet Base_Datos
A1: SISTEMA DE CONTROL DE INVENTARIO — DISTRIBUIDORA FMCG
A2: Base de Datos · 75 SKUs · Categorías: Alimentos Secos / Limpieza del Hogar / Higiene Personal · Período: Ene–Jun 2025
A4: SKU ID | B4: Descripción | C4: Categoría | D4: Cód. Proveedor | E4: Proveedor | F4: Precio Costo (USD) | G4: Stock Actual | H4: Stock Mínimo | I4: Ventas Ene-25 | J4: Ventas Feb-25 | K4: Ventas Mar-25 | L4: Ventas Abr-25 | M4: Ventas May-25 | N4: Ventas Jun-25 | O4: Total Ventas 6 meses | P4: Venta Prom. Mensual | Q4: Últ. Movimiento | R4: Días sin Movimiento | S4: Capital Inmovilizado (USD)
A5: ALIMENTOS SECOS
A6: SKU-001 | B6: Arroz Largo Fino 1kg | C6: Alimentos Secos | D6: PRV-001 | E6: Arrocera del Sur S.A. | F6: 3.2 | G6: 64 | H6: 14 | I6: 51 | J6: 61 | K6: 59 | L6: 78 | M6: 76 | N6: 84 | O6: =SUM(I6:N6) -> 409 | P6: =O6/6 -> 68.166667 | Q6: 45829 | R6: =DATE(2025,6,22)-Q6 -> 1 | S6: =G6*F6 -> 204.8
A7: SKU-002 | B7: Arroz Largo Fino 5kg | C7: Alimentos Secos | D7: PRV-001 | E7: Arrocera del Sur S.A. | F7: 14.5 | G7: 69 | H7: 14 | I7: 54 | J7: 64 | K7: 48 | L7: 54 | M7: 69 | N7: 66 | O7: =SUM(I7:N7) -> 355 | P7: =O7/6 -> 59.166667 | Q7: 45804 | R7: =DATE(2025,6,22)-Q7 -> 26 | S7: =G7*F7 -> 1000.5
A8: SKU-003 | B8: Fideos Spaghetti 500g | C8: Alimentos Secos | D8: PRV-002 | E8: Molinos Río de la Plata | F8: 1.8 | G8: 190 | H8: 8 | I8: 47 | J8: 34 | K8: 40 | L8: 37 | M8: 35 | N8: 47 | O8: =SUM(I8:N8) -> 240 | P8: =O8/6 -> 40 | Q8: 45818 | R8: =DATE(2025,6,22)-Q8 -> 12 | S8: =G8*F8 -> 342
A9: SKU-004 | B9: Fideos Moño 500g | C9: Alimentos Secos | D9: PRV-002 | E9: Molinos Río de la Plata | F9: 1.8 | G9: 248 | H9: 39 | I9: 138 | J9: 152 | K9: 147 | L9: 133 | M9: 164 | N9: 122 | O9: =SUM(I9:N9) -> 856 | P9: =O9/6 -> 142.66667 | Q9: 45810 | R9: =DATE(2025,6,22)-Q9 -> 20 | S9: =G9*F9 -> 446.4
A10: SKU-005 | B10: Harina 000 1kg | C10: Alimentos Secos | D10: PRV-003 | E10: Molinera Central S.R.L. | F10: 1.5 | G10: 24 | H10: 69 | I10: 460 | J10: 401 | K10: 427 | L10: 291 | M10: 329 | N10: 341 | O10: =SUM(I10:N10) -> 2249 | P10: =O10/6 -> 374.83333 | Q10: 45826 | R10: =DATE(2025,6,22)-Q10 -> 4 | S10: =G10*F10 -> 36
A11: SKU-006 | B11: Harina 0000 1kg | C11: Alimentos Secos | D11: PRV-003 | E11: Molinera Central S.R.L. | F11: 1.65 | G11: 308 | H11: 31 | I11: 123 | J11: 150 | K11: 130 | L11: 130 | M11: 118 | N11: 122 | O11: =SUM(I11:N11) -> 773 | P11: =O11/6 -> 128.83333 | Q11: 45810 | R11: =DATE(2025,6,22)-Q11 -> 20 | S11: =G11*F11 -> 508.2
A12: SKU-007 | B12: Azúcar Blanca 1kg | C12: Alimentos Secos | D12: PRV-004 | E12: Ingenio Azucarero Norte | F12: 1.4 | G12: 43 | H12: 6 | I12: 21 | J12: 28 | K12: 20 | L12: 23 | M12: 32 | N12: 27 | O12: =SUM(I12:N12) -> 151 | P12: =O12/6 -> 25.166667 | Q12: 45771 | R12: =DATE(2025,6,22)-Q12 -> 59 | S12: =G12*F12 -> 60.2
A13: SKU-008 | B13: Azúcar Morena 1kg | C13: Alimentos Secos | D13: PRV-004 | E13: Ingenio Azucarero Norte | F13: 1.6 | G13: 333 | H13: 9 | I13: 47 | J13: 41 | K13: 49 | L13: 48 | M13: 46 | N13: 68 | O13: =SUM(I13:N13) -> 299 | P13: =O13/6 -> 49.833333 | Q13: 45809 | R13: =DATE(2025,6,22)-Q13 -> 21 | S13: =G13*F13 -> 532.8
A14: SKU-009 | B14: Aceite de Girasol 900cc | C14: Alimentos Secos | D14: PRV-005 | E14: Aceites Nacionales S.A. | F14: 2.9 | G14: 209 | H14: 39 | I14: 161 | J14: 209 | K14: 167 | L14: 149 | M14: 147 | N14: 176 | O14: =SUM(I14:N14) -> 1009 | P14: =O14/6 -> 168.16667 | Q14: 45801 | R14: =DATE(2025,6,22)-Q14 -> 29 | S14: =G14*F14 -> 606.1
A15: SKU-010 | B15: Aceite de Girasol 1.8L | C15: Alimentos Secos | D15: PRV-005 | E15: Aceites Nacionales S.A. | F15: 5.5 | G15: 162 | H15: 26 | I15: 134 | J15: 184 | K15: 117 | L15: 145 | M15: 165 | N15: 173 | O15: =SUM(I15:N15) -> 918 | P15: =O15/6 -> 153 | Q15: 45808 | R15: =DATE(2025,6,22)-Q15 -> 22 | S15: =G15*F15 -> 891
A16: SKU-011 | B16: Aceite de Maíz 900cc | C16: Alimentos Secos | D16: PRV-005 | E16: Aceites Nacionales S.A. | F16: 3.2 | G16: 109 | H16: 5 | I16: 2 | J16: 2 | K16: 0 | L16: 2 | M16: 3 | N16: 1 | O16: =SUM(I16:N16) -> 10 | P16: =O16/6 -> 1.6666667 | Q16: 45722 | R16: =DATE(2025,6,22)-Q16 -> 108 | S16: =G16*F16 -> 348.8
A17: SKU-012 | B17: Sal Fina 1kg | C17: Alimentos Secos | D17: PRV-006 | E17: Salinera Patagónica | F17: 0.85 | G17: 88 | H17: 91 | I17: 428 | J17: 480 | K17: 437 | L17: 384 | M17: 302 | N17: 409 | O17: =SUM(I17:N17) -> 2440 | P17: =O17/6 -> 406.66667 | Q17: 45823 | R17: =DATE(2025,6,22)-Q17 -> 7 | S17: =G17*F17 -> 74.8
... A30: SKU-025 | B30: Porotos Negros 500g | C30: Alimentos Secos | D30: PRV-012 | E30: Legumbres del Norte | F30: 1.7 | G30: 304 | H30: 35 | I30: 159 | J30: 154 | K30: 193 | L30: 159 | M30: 155 | N30: 142 | O30: =SUM(I30:N30) -> 962 | P30: =O30/6 -> 160.33333 | Q30: 45800 | R30: =DATE(2025,6,22)-Q30 -> 30 | S30: =G30*F30 -> 516.8
A31: LIMPIEZA DEL HOGAR
A32: SKU-026 | B32: Lavandina Concentrada 1L | C32: Limpieza del Hogar | D32: PRV-013 | E32: Química Limpieza S.A. | F32: 1.2 | G32: 267 | H32: 11 | I32: 43 | J32: 63 | K32: 61 | L32: 46 | M32: 60 | N32: 59 | O32: =SUM(I32:N32) -> 332 | P32: =O32/6 -> 55.333333 | Q32: 45827 | R32: =DATE(2025,6,22)-Q32 -> 3 | S32: =G32*F32 -> 320.4
A33: SKU-027 | B33: Lavandina Clásica 2L | C33: Limpieza del Hogar | D33: PRV-013 | E33: Química Limpieza S.A. | F33: 1.8 | G33: 210 | H33: 16 | I33: 97 | J33: 85 | K33: 123 | L33: 115 | M33: 110 | N33: 131 | O33: =SUM(I33:N33) -> 661 | P33: =O33/6 -> 110.16667 | Q33: 45803 | R33: =DATE(2025,6,22)-Q33 -> 27 | S33: =G33*F33 -> 378
A34: SKU-028 | B34: Detergente Lavavajillas 500ml | C34: Limpieza del Hogar | D34: PRV-014 | E34: Unilever Argentina | F34: 2.4 | G34: 135 | H34: 24 | I34: 146 | J34: 93 | K34: 143 | L34: 103 | M34: 143 | N34: 134 | O34: =SUM(I34:N34) -> 762 | P34: =O34/6 -> 127 | Q34: 45823 | R34: =DATE(2025,6,22)-Q34 -> 7 | S34: =G34*F34 -> 324
A35: SKU-029 | B35: Detergente Lavavajillas 1L | C35: Limpieza del Hogar | D35: PRV-014 | E35: Unilever Argentina | F35: 4.2 | G35: 14 | H35: 5 | I35: 12 | J35: 16 | K35: 13 | L35: 15 | M35: 18 | N35: 18 | O35: =SUM(I35:N35) -> 92 | P35: =O35/6 -> 15.333333 | Q35: 45787 | R35: =DATE(2025,6,22)-Q35 -> 43 | S35: =G35*F35 -> 58.8
A36: SKU-030 | B36: Jabón en Polvo 1kg | C36: Limpieza del Hogar | D36: PRV-015 | E36: Procter & Gamble AR | F36: 4.8 | G36: 78 | H36: 7 | I36: 38 | J36: 59 | K36: 56 | L36: 45 | M36: 59 | N36: 53 | O36: =SUM(I36:N36) -> 310 | P36: =O36/6 -> 51.666667 | Q36: 45827 | R36: =DATE(2025,6,22)-Q36 -> 3 | S36: =G36*F36 -> 374.4
A37: SKU-031 | B37: Jabón en Polvo 3kg | C37: Limpieza del Hogar | D37: PRV-015 | E37: Procter & Gamble AR | F37: 13.5 | G37: 512 | H37: 20 | I37: 81 | J37: 94 | K37: 83 | L37: 64 | M37: 63 | N37: 71 | O37: =SUM(I37:N37) -> 456 | P37: =O37/6 -> 76 | Q37: 45802 | R37: =DATE(2025,6,22)-Q37 -> 28 | S37: =G37*F37 -> 6912
A38: SKU-032 | B38: Suavizante Ropa 800ml | C38: Limpieza del Hogar | D38: PRV-016 | E38: Henkel Argentina | F38: 3.6 | G38: 76 | H38: 12 | I38: 62 | J38: 43 | K38: 44 | L38: 40 | M38: 58 | N38: 61 | O38: =SUM(I38:N38) -> 308 | P38: =O38/6 -> 51.333333 | Q38: 45825 | R38: =DATE(2025,6,22)-Q38 -> 5 | S38: =G38*F38 -> 273.6
A39: SKU-033 | B39: Suavizante Ropa 1.5L | C39: Limpieza del Hogar | D39: PRV-016 | E39: Henkel Argentina | F39: 6.2 | G39: 185 | H39: 5 | I39: 1 | J39: 2 | K39: 1 | L39: 0 | M39: 3 | N39: 0 | O39: =SUM(I39:N39) -> 7 | P39: =O39/6 -> 1.1666667 | Q39: 45754 | R39: =DATE(2025,6,22)-Q39 -> 76 | S39: =G39*F39 -> 1147
A40: SKU-034 | B40: Limpiador Multiuso 500ml | C40: Limpieza del Hogar | D40: PRV-017 | E40: Reckitt Benckiser AR | F40: 2.9 | G40: 101 | H40: 17 | I40: 109 | J40: 91 | K40: 83 | L40: 108 | M40: 79 | N40: 69 | O40: =SUM(I40:N40) -> 539 | P40: =O40/6 -> 89.833333 | Q40: 45802 | R40: =DATE(2025,6,22)-Q40 -> 28 | S40: =G40*F40 -> 292.9
A41: SKU-035 | B41: Limpiador Piso 1L | C41: Limpieza del Hogar | D41: PRV-017 | E41: Reckitt Benckiser AR | F41: 3.1 | G41: 43 | H41: 30 | I41: 214 | J41: 150 | K41: 184 | L41: 161 | M41: 215 | N41: 174 | O41: =SUM(I41:N41) -> 1098 | P41: =O41/6 -> 183 | Q41: 45821 | R41: =DATE(2025,6,22)-Q41 -> 9 | S41: =G41*F41 -> 133.3
A42: SKU-036 | B42: Desengrasante 500ml | C42: Limpieza del Hogar | D42: PRV-018 | E42: Limpiadores del Sur | F42: 3.5 | G42: 137 | H42: 26 | I42: 90 | J42: 109 | K42: 65 | L42: 91 | M42: 79 | N42: 100 | O42: =SUM(I42:N42) -> 534 | P42: =O42/6 -> 89 | Q42: 45826 | R42: =DATE(2025,6,22)-Q42 -> 4 | S42: =G42*F42 -> 479.5
A43: SKU-037 | B43: Limpiavidrios 500ml | C43: Limpieza del Hogar | D43: PRV-018 | E43: Limpiadores del Sur | F43: 2.7 | G43: 274 | H43: 40 | I43: 171 | J43: 117 | K43: 106 | L43: 136 | M43: 142 | N43: 164 | O43: =SUM(I43:N43) -> 836 | P43: =O43/6 -> 139.33333 | Q43: 45806 | R43: =DATE(2025,6,22)-Q43 -> 24 | S43: =G43*F43 -> 739.8
... A56: SKU-050 | B56: Guantes de Látex Talle G | C56: Limpieza del Hogar | D56: PRV-024 | E56: Artículos del Hogar | F56: 2.6 | G56: 309 | H56: 42 | I56: 164 | J56: 173 | K56: 179 | L56: 184 | M56: 149 | N56: 178 | O56: =SUM(I56:N56) -> 1027 | P56: =O56/6 -> 171.16667 | Q56: 45827 | R56: =DATE(2025,6,22)-Q56 -> 3 | S56: =G56*F56 -> 803.4
A57: HIGIENE PERSONAL
A58: SKU-051 | B58: Jabón de Tocador x3 | C58: Higiene Personal | D58: PRV-025 | E58: Johnson & Johnson AR | F58: 3.2 | G58: 848 | H58: 27 | I58: 122 | J58: 149 | K58: 115 | L58: 142 | M58: 129 | N58: 138 | O58: =SUM(I58:N58) -> 795 | P58: =O58/6 -> 132.5 | Q58: 45805 | R58: =DATE(2025,6,22)-Q58 -> 25 | S58: =G58*F58 -> 2713.6
A59: SKU-052 | B59: Jabón Líquido 300ml | C59: Higiene Personal | D59: PRV-025 | E59: Johnson & Johnson AR | F59: 4.5 | G59: 31 | H59: 5 | I59: 15 | J59: 14 | K59: 13 | L59: 18 | M59: 23 | N59: 16 | O59: =SUM(I59:N59) -> 99 | P59: =O59/6 -> 16.5 | Q59: 45775 | R59: =DATE(2025,6,22)-Q59 -> 55 | S59: =G59*F59 -> 139.5
A60: SKU-053 | B60: Shampoo 400ml | C60: Higiene Personal | D60: PRV-026 | E60: L'Oréal Argentina | F60: 5.8 | G60: 91 | H60: 11 | I60: 58 | J60: 63 | K60: 42 | L60: 38 | M60: 41 | N60: 40 | O60: =SUM(I60:N60) -> 282 | P60: =O60/6 -> 47 | Q60: 45823 | R60: =DATE(2025,6,22)-Q60 -> 7 | S60: =G60*F60 -> 527.8
A61: SKU-054 | B61: Acondicionador 400ml | C61: Higiene Personal | D61: PRV-026 | E61: L'Oréal Argentina | F61: 5.8 | G61: 359 | H61: 48 | I61: 180 | J61: 186 | K61: 133 | L61: 172 | M61: 184 | N61: 129 | O61: =SUM(I61:N61) -> 984 | P61: =O61/6 -> 164 | Q61: 45826 | R61: =DATE(2025,6,22)-Q61 -> 4 | S61: =G61*F61 -> 2082.2
A62: SKU-055 | B62: Pasta Dental 90g | C62: Higiene Personal | D62: PRV-027 | E62: Colgate-Palmolive AR | F62: 2.4 | G62: 20 | H62: 77 | I62: 227 | J62: 274 | K62: 334 | L62: 380 | M62: 288 | N62: 340 | O62: =SUM(I62:N62) -> 1843 | P62: =O62/6 -> 307.16667 | Q62: 45809 | R62: =DATE(2025,6,22)-Q62 -> 21 | S62: =G62*F62 -> 48
A63: SKU-056 | B63: Pasta Dental 150g | C63: Higiene Personal | D63: PRV-027 | E63: Colgate-Palmolive AR | F63: 3.8 | G63: 230 | H63: 21 | I63: 82 | J63: 119 | K63: 124 | L63: 110 | M63: 83 | N63: 131 | O63: =SUM(I63:N63) -> 649 | P63: =O63/6 -> 108.16667 | Q63: 45816 | R63: =DATE(2025,6,22)-Q63 -> 14 | S63: =G63*F63 -> 874
A64: SKU-057 | B64: Cepillo de Dientes x2 | C64: Higiene Personal | D64: PRV-028 | E64: Oral-B Argentina | F64: 3.6 | G64: 678 | H64: 35 | I64: 105 | J64: 148 | K64: 101 | L64: 131 | M64: 136 | N64: 132 | O64: =SUM(I64:N64) -> 753 | P64: =O64/6 -> 125.5 | Q64: 45815 | R64: =DATE(2025,6,22)-Q64 -> 15 | S64: =G64*F64 -> 2440.8
A65: SKU-058 | B65: Desodorante Roll-On 65ml | C65: Higiene Personal | D65: PRV-029 | E65: Unilever Argentina | F65: 3.9 | G65: 139 | H65: 18 | I65: 78 | J65: 91 | K65: 101 | L65: 70 | M65: 94 | N65: 82 | O65: =SUM(I65:N65) -> 516 | P65: =O65/6 -> 86 | Q65: 45806 | R65: =DATE(2025,6,22)-Q65 -> 24 | S65: =G65*F65 -> 542.1
...

Sheet Análisis
A1: ANÁLISIS DE INVENTARIO — KPIs Y CLASIFICACIÓN
A2: Motor de cálculo automático · Todos los valores se actualizan al modificar Base_Datos · Fórmulas referenciadas en verde
A4: SKU ID | B4: Descripción | C4: Categoría | D4: Stock Actual | E4: Venta Prom. Mensual | F4: Días de Cobertura | G4: Índice de Rotación (x/mes) | H4: Capital Inmovilizado | I4: Stock Mínimo | J4: Días sin Movimiento | K4: Estado Cobertura | L4: Alerta Quiebre | M4: Clasif. ABC | N4: % sobre Total Ventas | O4: Acción Recomendada | P4: Prioridad
A5: =Base_Datos!A6 -> SKU-001 | B5: =Base_Datos!B6 -> Arroz Largo Fino 1kg | C5: =Base_Datos!C6 -> Alimentos Secos | D5: =Base_Datos!G6 -> 64 | E5: =Base_Datos!P6 -> 68.166667 | F5: =IFERROR(Base_Datos!G6/(Base_Datos!P6/30),9999) -> 28.166259 | G5: =IFERROR(Base_Datos!O6/Base_Datos!G6,0) -> 6.390625 | H5: =Base_Datos!S6 -> 204.8 | I5: =Base_Datos!H6 -> 14 | J5: =Base_Datos!R6 -> 1 | K5: =IF(IFERROR(Base_Datos!G6/(Base_Datos!P6/30),9999)<7,"🔴 QUIEBRE",IF(IFERROR(Base_Datos!G6/(Base_Datos!P6/30),9999)<14,"🟡 CRÍTICO",IF(IFERROR(Base_Datos!G6/(Base_Datos!P6/30),9999)<=90,"🟢 NORMAL",IF(IFERROR(Base_Datos!G6/(Base_Datos!P6/30),9999)<=180,"🟡 SOBRESTOCK","🔴 STOCK MUERTO")))) -> 🟢 NORMAL | L5: =IF(F5<7,"⚠ SÍ","—") -> — | M5: =IF(E5>=PERCENTILE($E$5:$E$79,0.8),"A",IF(E5>=PERCENTILE($E$5:$E$79,0.5),"B","C")) -> C | N5: =IFERROR(Base_Datos!O6/Base_Datos!O83,0) -> 0.0082922774 | O5: =IF(F5<7,"REPOSICIÓN URGENTE",IF(F5<14,"Revisar orden de compra",IF(AND(F5>180,J5>60),"LIQUIDAR / DEVOLVER",IF(F5>90,"Reducir próxima compra","Stock en niveles óptimos")))) -> Stock en niveles óptimos | P5: =IF(F5<7,1,IF(AND(F5>180,J5>60),2,IF(F5<14,3,IF(F5>90,4,5)))) -> 5
A6: =Base_Datos!A7 -> SKU-002 | B6: =Base_Datos!B7 -> Arroz Largo Fino 5kg | C6: =Base_Datos!C7 -> Alimentos Secos | D6: =Base_Datos!G7 -> 69 | E6: =Base_Datos!P7 -> 59.166667 | F6: =IFERROR(Base_Datos!G7/(Base_Datos!P7/30),9999) -> 34.985915 | G6: =IFERROR(Base_Datos!O7/Base_Datos!G7,0) -> 5.1449275 | H6: =Base_Datos!S7 -> 1000.5 | I6: =Base_Datos!H7 -> 14 | J6: =Base_Datos!R7 -> 26 | K6: =IF(IFERROR(Base_Datos!G7/(Base_Datos!P7/30),9999)<7,"🔴 QUIEBRE",IF(IFERROR(Base_Datos!G7/(Base_Datos!P7/30),9999)<14,"🟡 CRÍTICO",IF(IFERROR(Base_Datos!G7/(Base_Datos!P7/30),9999)<=90,"🟢 NORMAL",IF(IFERROR(Base_Datos!G7/(Base_Datos!P7/30),9999)<=180,"🟡 SOBRESTOCK","🔴 STOCK MUERTO")))) -> 🟢 NORMAL | L6: =IF(F6<7,"⚠ SÍ","—") -> — | M6: =IF(E6>=PERCENTILE($E$5:$E$79,0.8),"A",IF(E6>=PERCENTILE($E$5:$E$79,0.5),"B","C")) -> C | N6: =IFERROR(Base_Datos!O7/Base_Datos!O83,0) -> 0.0071974535 | O6: =IF(F6<7,"REPOSICIÓN URGENTE",IF(F6<14,"Revisar orden de compra",IF(AND(F6>180,J6>60),"LIQUIDAR / DEVOLVER",IF(F6>90,"Reducir próxima compra","Stock en niveles óptimos")))) -> Stock en niveles óptimos | P6: =IF(F6<7,1,IF(AND(F6>180,J6>60),2,IF(F6<14,3,IF(F6>90,4,5)))) -> 5
A7: =Base_Datos!A8 -> SKU-003 | B7: =Base_Datos!B8 -> Fideos Spaghetti 500g | C7: =Base_Datos!C8 -> Alimentos Secos | D7: =Base_Datos!G8 -> 190 | E7: =Base_Datos!P8 -> 40 | F7: =IFERROR(Base_Datos!G8/(Base_Datos!P8/30),9999) -> 142.5 | G7: =IFERROR(Base_Datos!O8/Base_Datos!G8,0) -> 1.2631579 | H7: =Base_Datos!S8 -> 342 | I7: =Base_Datos!H8 -> 8 | J7: =Base_Datos!R8 -> 12 | K7: =IF(IFERROR(Base_Datos!G8/(Base_Datos!P8/30),9999)<7,"🔴 QUIEBRE",IF(IFERROR(Base_Datos!G8/(Base_Datos!P8/30),9999)<14,"🟡 CRÍTICO",IF(IFERROR(Base_Datos!G8/(Base_Datos!P8/30),9999)<=90,"🟢 NORMAL",IF(IFERROR(Base_Datos!G8/(Base_Datos!P8/30),9999)<=180,"🟡 SOBRESTOCK","🔴 STOCK MUERTO")))) -> 🟡 SOBRESTOCK | L7: =IF(F7<7,"⚠ SÍ","—") -> — | M7: =IF(E7>=PERCENTILE($E$5:$E$79,0.8),"A",IF(E7>=PERCENTILE($E$5:$E$79,0.5),"B","C")) -> C | N7: =IFERROR(Base_Datos!O8/Base_Datos!O83,0) -> 0.0048658841 | O7: =IF(F7<7,"REPOSICIÓN URGENTE",IF(F7<14,"Revisar orden de compra",IF(AND(F7>180,J7>60),"LIQUIDAR / DEVOLVER",IF(F7>90,"Reducir próxima compra","Stock en niveles óptimos")))) -> Reducir próxima compra | P7: =IF(F7<7,1,IF(AND(F7>180,J7>60),2,IF(F7<14,3,IF(F7>90,4,5)))) -> 4
A8: =Base_Datos!A9 -> SKU-004 | B8: =Base_Datos!B9 -> Fideos Moño 500g | C8: =Base_Datos!C9 -> Alimentos Secos | D8: =Base_Datos!G9 -> 248 | E8: =Base_Datos!P9 -> 142.66667 | F8: =IFERROR(Base_Datos!G9/(Base_Datos!P9/30),9999) -> 52.149533 | G8: =IFERROR(Base_Datos!O9/Base_Datos!G9,0) -> 3.4516129 | H8: =Base_Datos!S9 -> 446.4 | I8: =Base_Datos!H9 -> 39 | J8: =Base_Datos!R9 -> 20 | K8: =IF(IFERROR(Base_Datos!G9/(Base_Datos!P9/30),9999)<7,"🔴 QUIEBRE",IF(IFERROR(Base_Datos!G9/(Base_Datos!P9/30),9999)<14,"🟡 CRÍTICO",IF(IFERROR(Base_Datos!G9/(Base_Datos!P9/30),9999)<=90,"🟢 NORMAL",IF(IFERROR(Base_Datos!G9/(Base_Datos!P9/30),9999)<=180,"🟡 SOBRESTOCK","🔴 STOCK MUERTO")))) -> 🟢 NORMAL | L8: =IF(F8<7,"⚠ SÍ","—") -> — | M8: =IF(E8>=PERCENTILE($E$5:$E$79,0.8),"A",IF(E8>=PERCENTILE($E$5:$E$79,0.5),"B","C")) -> B | N8: =IFERROR(Base_Datos!O9/Base_Datos!O83,0) -> 0.017354987 | O8: =IF(F8<7,"REPOSICIÓN URGENTE",IF(F8<14,"Revisar orden de compra",IF(AND(F8>180,J8>60),"LIQUIDAR / DEVOLVER",IF(F8>90,"Reducir próxima compra","Stock en niveles óptimos")))) -> Stock en niveles óptimos | P8: =IF(F8<7,1,IF(AND(F8>180,J8>60),2,IF(F8<14,3,IF(F8>90,4,5)))) -> 5
A9: =Base_Datos!A10 -> SKU-005 | B9: =Base_Datos!B10 -> Harina 000 1kg | C9: =Base_Datos!C10 -> Alimentos Secos | D9: =Base_Datos!G10 -> 24 | E9: =Base_Datos!P10 -> 374.83333 | F9: =IFERROR(Base_Datos!G10/(Base_Datos!P10/30),9999) -> 1.9208537 | G9: =IFERROR(Base_Datos!O10/Base_Datos!G10,0) -> 93.708333 | H9: =Base_Datos!S10 -> 36 | I9: =Base_Datos!H10 -> 69 | J9: =Base_Datos!R10 -> 4 | K9: =IF(IFERROR(Base_Datos!G10/(Base_Datos!P10/30),9999)<7,"🔴 QUIEBRE",IF(IFERROR(Base_Datos!G10/(Base_Datos!P10/30),9999)<14,"🟡 CRÍTICO",IF(IFERROR(Base_Datos!G10/(Base_Datos!P10/30),9999)<=90,"🟢 NORMAL",IF(IFERROR(Base_Datos!G10/(Base_Datos!P10/30),9999)<=180,"🟡 SOBRESTOCK","🔴 STOCK MUERTO")))) -> 🔴 QUIEBRE | L9: =IF(F9<7,"⚠ SÍ","—") -> ⚠ SÍ | M9: =IF(E9>=PERCENTILE($E$5:$E$79,0.8),"A",IF(E9>=PERCENTILE($E$5:$E$79,0.5),"B","C")) -> A | N9: =IFERROR(Base_Datos!O10/Base_Datos!O83,0) -> 0.045597389 | O9: =IF(F9<7,"REPOSICIÓN URGENTE",IF(F9<14,"Revisar orden de compra",IF(AND(F9>180,J9>60),"LIQUIDAR / DEVOLVER",IF(F9>90,"Reducir próxima compra","Stock en niveles óptimos")))) -> REPOSICIÓN URGENTE | P9: =IF(F9<7,1,IF(AND(F9>180,J9>60),2,IF(F9<14,3,IF(F9>90,4,5)))) -> 1
A10: =Base_Datos!A11 -> SKU-006 | B10: =Base_Datos!B11 -> Harina 0000 1kg | C10: =Base_Datos!C11 -> Alimentos Secos | D10: =Base_Datos!G11 -> 308 | E10: =Base_Datos!P11 -> 128.83333 | F10: =IFERROR(Base_Datos!G11/(Base_Datos!P11/30),9999) -> 71.720569 | G10: =IFERROR(Base_Datos!O11/Base_Datos!G11,0) -> 2.5097403 | H10: =Base_Datos!S11 -> 508.2 | I10: =Base_Datos!H11 -> 31 | J10: =Base_Datos!R11 -> 20 | K10: =IF(IFERROR(Base_Datos!G11/(Base_Datos!P11/30),9999)<7,"🔴 QUIEBRE",IF(IFERROR(Base_Datos!G11/(Base_Datos!P11/30),9999)<14,"🟡 CRÍTICO",IF(IFERROR(Base_Datos!G11/(Base_Datos!P11/30),9999)<=90,"🟢 NORMAL",IF(IFERROR(Base_Datos!G11/(Base_Datos!P11/30),9999)<=180,"🟡 SOBRESTOCK","🔴 STOCK MUERTO")))) -> 🟢 NORMAL | L10: =IF(F10<7,"⚠ SÍ","—") -> — | M10: =IF(E10>=PERCENTILE($E$5:$E$79,0.8),"A",IF(E10>=PERCENTILE($E$5:$E$79,0.5),"B","C")) -> B | N10: =IFERROR(Base_Datos!O11/Base_Datos!O83,0) -> 0.015672202 | O10: =IF(F10<7,"REPOSICIÓN URGENTE",IF(F10<14,"Revisar orden de compra",IF(AND(F10>180,J10>60),"LIQUIDAR / DEVOLVER",IF(F10>90,"Reducir próxima compra","Stock en niveles óptimos")))) -> Stock en niveles óptimos | P10: =IF(F10<7,1,IF(AND(F10>180,J10>60),2,IF(F10<14,3,IF(F10>90,4,5)))) -> 5
A11: =Base_Datos!A12 -> SKU-007 | B11: =Base_Datos!B12 -> Azúcar Blanca 1kg | C11: =Base_Datos!C12 -> Alimentos Secos | D11: =Base_Datos!G12 -> 43 | E11: =Base_Datos!P12 -> 25.166667 | F11: =IFERROR(Base_Datos!G12/(Base_Datos!P12/30),9999) -> 51.258278 | G11: =IFERROR(Base_Datos!O12/Base_Datos!G12,0) -> 3.5116279 | H11: =Base_Datos!S12 -> 60.2 | I11: =Base_Datos!H12 -> 6 | J11: =Base_Datos!R12 -> 59 | K11: =IF(IFERROR(Base_Datos!G12/(Base_Datos!P12/30),9999)<7,"🔴 QUIEBRE",IF(IFERROR(Base_Datos!G12/(Base_Datos!P12/30),9999)<14,"🟡 CRÍTICO",IF(IFERROR(Base_Datos!G12/(Base_Datos!P12/30),9999)<=90,"🟢 NORMAL",IF(IFERROR(Base_Datos!G12/(Base_Datos!P12/30),9999)<=180,"🟡 SOBRESTOCK","🔴 STOCK MUERTO")))) -> 🟢 NORMAL | L11: =IF(F11<7,"⚠ SÍ","—") -> — | M11: =IF(E11>=PERCENTILE($E$5:$E$79,0.8),"A",IF(E11>=PERCENTILE($E$5:$E$79,0.5),"B","C")) -> C | N11: =IFERROR(Base_Datos!O12/Base_Datos!O83,0) -> 0.0030614521 | O11: =IF(F11<7,"REPOSICIÓN URGENTE",IF(F11<14,"Revisar orden de compra",IF(AND(F11>180,J11>60),"LIQUIDAR / DEVOLVER",IF(F11>90,"Reducir próxima compra","Stock en niveles óptimos")))) -> Stock en niveles óptimos | P11: =IF(F11<7,1,IF(AND(F11>180,J11>60),2,IF(F11<14,3,IF(F11>90,4,5)))) -> 5
A12: =Base_Datos!A13 -> SKU-008 | B12: =Base_Datos!B13 -> Azúcar Morena 1kg | C12: =Base_Datos!C13 -> Alimentos Secos | D12: =Base_Datos!G13 -> 333 | E12: =Base_Datos!P13 -> 49.833333 | F12: =IFERROR(Base_Datos!G13/(Base_Datos!P13/30),9999) -> 200.46823 | G12: =IFERROR(Base_Datos!O13/Base_Datos!G13,0) -> 0.8978979 | H12: =Base_Datos!S13 -> 532.8 | I12: =Base_Datos!H13 -> 9 | J12: =Base_Datos!R13 -> 21 | K12: =IF(IFERROR(Base_Datos!G13/(Base_Datos!P13/30),9999)<7,"🔴 QUIEBRE",IF(IFERROR(Base_Datos!G13/(Base_Datos!P13/30),9999)<14,"🟡 CRÍTICO",IF(IFERROR(Base_Datos!G13/(Base_Datos!P13/30),9999)<=90,"🟢 NORMAL",IF(IFERROR(Base_Datos!G13/(Base_Datos!P13/30),9999)<=180,"🟡 SOBRESTOCK","🔴 STOCK MUERTO")))) -> 🔴 STOCK MUERTO | L12: =IF(F12<7,"⚠ SÍ","—") -> — | M12: =IF(E12>=PERCENTILE($E$5:$E$79,0.8),"A",IF(E12>=PERCENTILE($E$5:$E$79,0.5),"B","C")) -> C | N12: =IFERROR(Base_Datos!O13/Base_Datos!O83,0) -> 0.0060620806 | O12: =IF(F12<7,"REPOSICIÓN URGENTE",IF(F12<14,"Revisar orden de compra",IF(AND(F12>180,J12>60),"LIQUIDAR / DEVOLVER",IF(F12>90,"Reducir próxima compra","Stock en niveles óptimos")))) -> Reducir próxima compra | P12: =IF(F12<7,1,IF(AND(F12>180,J12>60),2,IF(F12<14,3,IF(F12>90,4,5)))) -> 4
A13: =Base_Datos!A14 -> SKU-009 | B13: =Base_Datos!B14 -> Aceite de Girasol 900cc | C13: =Base_Datos!C14 -> Alimentos Secos | D13: =Base_Datos!G14 -> 209 | E13: =Base_Datos!P14 -> 168.16667 | F13: =IFERROR(Base_Datos!G14/(Base_Datos!P14/30),9999) -> 37.28444 | G13: =IFERROR(Base_Datos!O14/Base_Datos!G14,0) -> 4.8277512 | H13: =Base_Datos!S14 -> 606.1 | I13: =Base_Datos!H14 -> 39 | J13: =Base_Datos!R14 -> 29 | K13: =IF(IFERROR(Base_Datos!G14/(Base_Datos!P14/30),9999)<7,"🔴 QUIEBRE",IF(IFERROR(Base_Datos!G14/(Base_Datos!P14/30),9999)<14,"🟡 CRÍTICO",IF(IFERROR(Base_Datos!G14/(Base_Datos!P14/30),9999)<=90,"🟢 NORMAL",IF(IFERROR(Base_Datos!G14/(Base_Datos!P14/30),9999)<=180,"🟡 SOBRESTOCK","🔴 STOCK MUERTO")))) -> 🟢 NORMAL | L13: =IF(F13<7,"⚠ SÍ","—") -> — | M13: =IF(E13>=PERCENTILE($E$5:$E$79,0.8),"A",IF(E13>=PERCENTILE($E$5:$E$79,0.5),"B","C")) -> A | N13: =IFERROR(Base_Datos!O14/Base_Datos!O83,0) -> 0.020456988 | O13: =IF(F13<7,"REPOSICIÓN URGENTE",IF(F13<14,"Revisar orden de compra",IF(AND(F13>180,J13>60),"LIQUIDAR / DEVOLVER",IF(F13>90,"Reducir próxima compra","Stock en niveles óptimos")))) -> Stock en niveles óptimos | P13: =IF(F13<7,1,IF(AND(F13>180,J13>60),2,IF(F13<14,3,IF(F13>90,4,5)))) -> 5
A14: =Base_Datos!A15 -> SKU-010 | B14: =Base_Datos!B15 -> Aceite de Girasol 1.8L | C14: =Base_Datos!C15 -> Alimentos Secos | D14: =Base_Datos!G15 -> 162 | E14: =Base_Datos!P15 -> 153 | F14: =IFERROR(Base_Datos!G15/(Base_Datos!P15/30),9999) -> 31.764706 | G14: =IFERROR(Base_Datos!O15/Base_Datos!G15,0) -> 5.6666667 | H14: =Base_Datos!S15 -> 891 | I14: =Base_Datos!H15 -> 26 | J14: =Base_Datos!R15 -> 22 | K14: =IF(IFERROR(Base_Datos!G15/(Base_Datos!P15/30),9999)<7,"🔴 QUIEBRE",IF(IFERROR(Base_Datos!G15/(Base_Datos!P15/30),9999)<14,"🟡 CRÍTICO",IF(IFERROR(Base_Datos!G15/(Base_Datos!P15/30),9999)<=90,"🟢 NORMAL",IF(IFERROR(Base_Datos!G15/(Base_Datos!P15/30),9999)<=180,"🟡 SOBRESTOCK","🔴 STOCK MUERTO")))) -> 🟢 NORMAL | L14: =IF(F14<7,"⚠ SÍ","—") -> — | M14: =IF(E14>=PERCENTILE($E$5:$E$79,0.8),"A",IF(E14>=PERCENTILE($E$5:$E$79,0.5),"B","C")) -> B | N14: =IFERROR(Base_Datos!O15/Base_Datos!O83,0) -> 0.018612007 | O14: =IF(F14<7,"REPOSICIÓN URGENTE",IF(F14<14,"Revisar orden de compra",IF(AND(F14>180,J14>60),"LIQUIDAR / DEVOLVER",IF(F14>90,"Reducir próxima compra","Stock en niveles óptimos")))) -> Stock en niveles óptimos | P14: =IF(F14<7,1,IF(AND(F14>180,J14>60),2,IF(F14<14,3,IF(F14>90,4,5)))) -> 5
A15: =Base_Datos!A16 -> SKU-011 | B15: =Base_Datos!B16 -> Aceite de Maíz 900cc | C15: =Base_Datos!C16 -> Alimentos Secos | D15: =Base_Datos!G16 -> 109 | E15: =Base_Datos!P16 -> 1.6666667 | F15: =IFERROR(Base_Datos!G16/(Base_Datos!P16/30),9999) -> 1962 | G15: =IFERROR(Base_Datos!O16/Base_Datos!G16,0) -> 0.091743119 | H15: =Base_Datos!S16 -> 348.8 | I15: =Base_Datos!H16 -> 5 | J15: =Base_Datos!R16 -> 108 | K15: =IF(IFERROR(Base_Datos!G16/(Base_Datos!P16/30),9999)<7,"🔴 QUIEBRE",IF(IFERROR(Base_Datos!G16/(Base_Datos!P16/30),9999)<14,"🟡 CRÍTICO",IF(IFERROR(Base_Datos!G16/(Base_Datos!P16/30),9999)<=90,"🟢 NORMAL",IF(IFERROR(Base_Datos!G16/(Base_Datos!P16/30),9999)<=180,"🟡 SOBRESTOCK","🔴 STOCK MUERTO")))) -> 🔴 STOCK MUERTO | L15: =IF(F15<7,"⚠ SÍ","—") -> — | M15: =IF(E15>=PERCENTILE($E$5:$E$79,0.8),"A",IF(E15>=PERCENTILE($E$5:$E$79,0.5),"B","C")) -> C | N15: =IFERROR(Base_Datos!O16/Base_Datos!O83,0) -> 0.00020274517 | O15: =IF(F15<7,"REPOSICIÓN URGENTE",IF(F15<14,"Revisar orden de compra",IF(AND(F15>180,J15>60),"LIQUIDAR / DEVOLVER",IF(F15>90,"Reducir próxima compra","Stock en niveles óptimos")))) -> LIQUIDAR / DEVOLVER | P15: =IF(F15<7,1,IF(AND(F15>180,J15>60),2,IF(F15<14,3,IF(F15>90,4,5)))) -> 2
A16: =Base_Datos!A17 -> SKU-012 | B16: =Base_Datos!B17 -> Sal Fina 1kg | C16: =Base_Datos!C17 -> Alimentos Secos | D16: =Base_Datos!G17 -> 88 | E16: =Base_Datos!P17 -> 406.66667 | F16: =IFERROR(Base_Datos!G17/(Base_Datos!P17/30),9999) -> 6.4918033 | G16: =IFERROR(Base_Datos!O17/Base_Datos!G17,0) -> 27.727273 | H16: =Base_Datos!S17 -> 74.8 | I16: =Base_Datos!H17 -> 91 | J16: =Base_Datos!R17 -> 7 | K16: =IF(IFERROR(Base_Datos!G17/(Base_Datos!P17/30),9999)<7,"🔴 QUIEBRE",IF(IFERROR(Base_Datos!G17/(Base_Datos!P17/30),9999)<14,"🟡 CRÍTICO",IF(IFERROR(Base_Datos!G17/(Base_Datos!P17/30),9999)<=90,"🟢 NORMAL",IF(IFERROR(Base_Datos!G17/(Base_Datos!P17/30),9999)<=180,"🟡 SOBRESTOCK","🔴 STOCK MUERTO")))) -> 🔴 QUIEBRE | L16: =IF(F16<7,"⚠ SÍ","—") -> ⚠ SÍ | M16: =IF(E16>=PERCENTILE($E$5:$E$79,0.8),"A",IF(E16>=PERCENTILE($E$5:$E$79,0.5),"B","C")) -> A | N16: =IFERROR(Base_Datos!O17/Base_Datos!O83,0) -> 0.049469821 | O16: =IF(F16<7,"REPOSICIÓN URGENTE",IF(F16<14,"Revisar orden de compra",IF(AND(F16>180,J16>60),"LIQUIDAR / DEVOLVER",IF(F16>90,"Reducir próxima compra","Stock en niveles óptimos")))) -> REPOSICIÓN URGENTE | P16: =IF(F16<7,1,IF(AND(F16>180,J16>60),2,IF(F16<14,3,IF(F16>90,4,5)))) -> 1
A17: =Base_Datos!A18 -> SKU-013 | B17: =Base_Datos!B18 -> Sal Gruesa 1kg | C17: =Base_Datos!C18 -> Alimentos Secos | D17: =Base_Datos!G18 -> 142 | E17: =Base_Datos!P18 -> 87.333333 | F17: =IFERROR(Base_Datos!G18/(Base_Datos!P18/30),9999) -> 48.778626 | G17: =IFERROR(Base_Datos!O18/Base_Datos!G18,0) -> 3.6901408 | H17: =Base_Datos!S18 -> 113.6 | I17: =Base_Datos!H18 -> 14 | J17: =Base_Datos!R18 -> 12 | K17: =IF(IFERROR(Base_Datos!G18/(Base_Datos!P18/30),9999)<7,"🔴 QUIEBRE",IF(IFERROR(Base_Datos!G18/(Base_Datos!P18/30),9999)<14,"🟡 CRÍTICO",IF(IFERROR(Base_Datos!G18/(Base_Datos!P18/30),9999)<=90,"🟢 NORMAL",IF(IFERROR(Base_Datos!G18/(Base_Datos!P18/30),9999)<=180,"🟡 SOBRESTOCK","🔴 STOCK MUERTO")))) -> 🟢 NORMAL | L17: =IF(F17<7,"⚠ SÍ","—") -> — | M17: =IF(E17>=PERCENTILE($E$5:$E$79,0.8),"A",IF(E17>=PERCENTILE($E$5:$E$79,0.5),"B","C")) -> C | N17: =IFERROR(Base_Datos!O18/Base_Datos!O83,0) -> 0.010623847 | O17: =IF(F17<7,"REPOSICIÓN URGENTE",IF(F17<14,"Revisar orden de compra",IF(AND(F17>180,J17>60),"LIQUIDAR / DEVOLVER",IF(F17>90,"Reducir próxima compra","Stock en niveles óptimos")))) -> Stock en niveles óptimos | P17: =IF(F17<7,1,IF(AND(F17>180,J17>60),2,IF(F17<14,3,IF(F17>90,4,5)))) -> 5
A18: =Base_Datos!A19 -> SKU-014 | B18: =Base_Datos!B19 -> Yerba Mate 500g | C18: =Base_Datos!C19 -> Alimentos Secos | D18: =Base_Datos!G19 -> 288 | E18: =Base_Datos!P19 -> 117.16667 | F18: =IFERROR(Base_Datos!G19/(Base_Datos!P19/30),9999) -> 73.74111 | G18: =IFERROR(Base_Datos!O19/Base_Datos!G19,0) -> 2.4409722 | H18: =Base_Datos!S19 -> 1094.4 | I18: =Base_Datos!H19 -> 26 | J18: =Base_Datos!R19 -> 5 | K18: =IF(IFERROR(Base_Datos!G19/(Base_Datos!P19/30),9999)<7,"🔴 QUIEBRE",IF(IFERROR(Base_Datos!G19/(Base_Datos!P19/30),9999)<14,"🟡 CRÍTICO",IF(IFERROR(Base_Datos!G19/(Base_Datos!P19/30),9999)<=90,"🟢 NORMAL",IF(IFERROR(Base_Datos!G19/(Base_Datos!P19/30),9999)<=180,"🟡 SOBRESTOCK","🔴 STOCK MUERTO")))) -> 🟢 NORMAL | L18: =IF(F18<7,"⚠ SÍ","—") -> — | M18: =IF(E18>=PERCENTILE($E$5:$E$79,0.8),"A",IF(E18>=PERCENTILE($E$5:$E$79,0.5),"B","C")) -> B | N18: =IFERROR(Base_Datos!O19/Base_Datos!O83,0) -> 0.014252985 | O18: =IF(F18<7,"REPOSICIÓN URGENTE",IF(F18<14,"Revisar orden de compra",IF(AND(F18>180,J18>60),"LIQUIDAR / DEVOLVER",IF(F18>90,"Reducir próxima compra","Stock en niveles óptimos")))) -> Stock en niveles óptimos | P18: =IF(F18<7,1,IF(AND(F18>180,J18>60),2,IF(F18<14,3,IF(F18>90,4,5)))) -> 5
A19: =Base_Datos!A20 -> SKU-015 | B19: =Base_Datos!B20 -> Yerba Mate 1kg | C19: =Base_Datos!C20 -> Alimentos Secos | D19: =Base_Datos!G20 -> 540 | E19: =Base_Datos!P20 -> 79.166667 | F19: =IFERROR(Base_Datos!G20/(Base_Datos!P20/30),9999) -> 204.63158 | G19: =IFERROR(Base_Datos!O20/Base_Datos!G20,0) -> 0.87962963 | H19: =Base_Datos!S20 -> 3888 | I19: =Base_Datos!H20 -> 20 | J19: =Base_Datos!R20 -> 23 | K19: =IF(IFERROR(Base_Datos!G20/(Base_Datos!P20/30),9999)<7,"🔴 QUIEBRE",IF(IFERROR(Base_Datos!G20/(Base_Datos!P20/30),9999)<14,"🟡 CRÍTICO",IF(IFERROR(Base_Datos!G20/(Base_Datos!P20/30),9999)<=90,"🟢 NORMAL",IF(IFERROR(Base_Datos!G20/(Base_Datos!P20/30),9999)<=180,"🟡 SOBRESTOCK","🔴 STOCK MUERTO")))) -> 🔴 STOCK MUERTO | L19: =IF(F19<7,"⚠ SÍ","—") -> — | M19: =IF(E19>=PERCENTILE($E$5:$E$79,0.8),"A",IF(E19>=PERCENTILE($E$5:$E$79,0.5),"B","C")) -> C | N19: =IFERROR(Base_Datos!O20/Base_Datos!O83,0) -> 0.0096303956 | O19: =IF(F19<7,"REPOSICIÓN URGENTE",IF(F19<14,"Revisar orden de compra",IF(AND(F19>180,J19>60),"LIQUIDAR / DEVOLVER",IF(F19>90,"Reducir próxima compra","Stock en niveles óptimos")))) -> Reducir próxima compra | P19: =IF(F19<7,1,IF(AND(F19>180,J19>60),2,IF(F19<14,3,IF(F19>90,4,5)))) -> 4
A20: =Base_Datos!A21 -> SKU-016 | B20: =Base_Datos!B21 -> Café Molido 250g | C20: =Base_Datos!C21 -> Alimentos Secos | D20: =Base_Datos!G21 -> 13 | E20: =Base_Datos!P21 -> 11.166667 | F20: =IFERROR(Base_Datos!G21/(Base_Datos!P21/30),9999) -> 34.925373 | G20: =IFERROR(Base_Datos!O21/Base_Datos!G21,0) -> 5.1538462 | H20: =Base_Datos!S21 -> 58.5 | I20: =Base_Datos!H21 -> 5 | J20: =Base_Datos!R21 -> 35 | K20: =IF(IFERROR(Base_Datos!G21/(Base_Datos!P21/30),9999)<7,"🔴 QUIEBRE",IF(IFERROR(Base_Datos!G21/(Base_Datos!P21/30),9999)<14,"🟡 CRÍTICO",IF(IFERROR(Base_Datos!G21/(Base_Datos!P21/30),9999)<=90,"🟢 NORMAL",IF(IFERROR(Base_Datos!G21/(Base_Datos!P21/30),9999)<=180,"🟡 SOBRESTOCK","🔴 STOCK MUERTO")))) -> 🟢 NORMAL | L20: =IF(F20<7,"⚠ SÍ","—") -> — | M20: =IF(E20>=PERCENTILE($E$5:$E$79,0.8),"A",IF(E20>=PERCENTILE($E$5:$E$79,0.5),"B","C")) -> C | N20: =IFERROR(Base_Datos!O21/Base_Datos!O83,0) -> 0.0013583926 | O20: =IF(F20<7,"REPOSICIÓN URGENTE",IF(F20<14,"Revisar orden de compra",IF(AND(F20>180,J20>60),"LIQUIDAR / DEVOLVER",IF(F20>90,"Reducir próxima compra","Stock en niveles óptimos")))) -> Stock en niveles óptimos | P20: =IF(F20<7,1,IF(AND(F20>180,J20>60),2,IF(F20<14,3,IF(F20>90,4,5)))) -> 5
A21: =Base_Datos!A22 -> SKU-017 | B21: =Base_Datos!B22 -> Té en Saquitos x20 | C21: =Base_Datos!C22 -> Alimentos Secos | D21: =Base_Datos!G22 -> 117 | E21: =Base_Datos!P22 -> 86.166667 | F21: =IFERROR(Base_Datos!G22/(Base_Datos!P22/30),9999) -> 40.73501 | G21: =IFERROR(Base_Datos!O22/Base_Datos!G22,0) -> 4.4188034 | H21: =Base_Datos!S22 -> 245.7 | I21: =Base_Datos!H22 -> 19 | J21: =Base_Datos!R22 -> 9 | K21: =IF(IFERROR(Base_Datos!G22/(Base_Datos!P22/30),9999)<7,"🔴 QUIEBRE",IF(IFERROR(Base_Datos!G22/(Base_Datos!P22/30),9999)<14,"🟡 CRÍTICO",IF(IFERROR(Base_Datos!G22/(Base_Datos!P22/30),9999)<=90,"🟢 NORMAL",IF(IFERROR(Base_Datos!G22/(Base_Datos!P22/30),9999)<=180,"🟡 SOBRESTOCK","🔴 STOCK MUERTO")))) -> 🟢 NORMAL | L21: =IF(F21<7,"⚠ SÍ","—") -> — | M21: =IF(E21>=PERCENTILE($E$5:$E$79,0.8),"A",IF(E21>=PERCENTILE($E$5:$E$79,0.5),"B","C")) -> C | N21: =IFERROR(Base_Datos!O22/Base_Datos!O83,0) -> 0.010481925 | O21: =IF(F21<7,"REPOSICIÓN URGENTE",IF(F21<14,"Revisar orden de compra",IF(AND(F21>180,J21>60),"LIQUIDAR / DEVOLVER",IF(F21>90,"Reducir próxima compra","Stock en niveles óptimos")))) -> Stock en niveles óptimos | P21: =IF(F21<7,1,IF(AND(F21>180,J21>60),2,IF(F21<14,3,IF(F21>90,4,5)))) -> 5
A22: =Base_Datos!A23 -> SKU-018 | B22: =Base_Datos!B23 -> Galletitas Dulces 200g | C22: =Base_Datos!C23 -> Alimentos Secos | D22: =Base_Datos!G23 -> 367 | E22: =Base_Datos!P23 -> 169.16667 | F22: =IFERROR(Base_Datos!G23/(Base_Datos!P23/30),9999) -> 65.083744 | G22: =IFERROR(Base_Datos!O23/Base_Datos!G23,0) -> 2.7656676 | H22: =Base_Datos!S23 -> 697.3 | I22: =Base_Datos!H23 -> 30 | J22: =Base_Datos!R23 -> 4 | K22: =IF(IFERROR(Base_Datos!G23/(Base_Datos!P23/30),9999)<7,"🔴 QUIEBRE",IF(IFERROR(Base_Datos!G23/(Base_Datos!P23/30),9999)<14,"🟡 CRÍTICO",IF(IFERROR(Base_Datos!G23/(Base_Datos!P23/30),9999)<=90,"🟢 NORMAL",IF(IFERROR(Base_Datos!G23/(Base_Datos!P23/30),9999)<=180,"🟡 SOBRESTOCK","🔴 STOCK MUERTO")))) -> 🟢 NORMAL | L22: =IF(F22<7,"⚠ SÍ","—") -> — | M22: =IF(E22>=PERCENTILE($E$5:$E$79,0.8),"A",IF(E22>=PERCENTILE($E$5:$E$79,0.5),"B","C")) -> A | N22: =IFERROR(Base_Datos!O23/Base_Datos!O83,0) -> 0.020578635 | O22: =IF(F22<7,"REPOSICIÓN URGENTE",IF(F22<14,"Revisar orden de compra",IF(AND(F22>180,J22>60),"LIQUIDAR / DEVOLVER",IF(F22>90,"Reducir próxima compra","Stock en niveles óptimos")))) -> Stock en niveles óptimos | P22: =IF(F22<7,1,IF(AND(F22>180,J22>60),2,IF(F22<14,3,IF(F22>90,4,5)))) -> 5
A23: =Base_Datos!A24 -> SKU-019 | B23: =Base_Datos!B24 -> Galletitas Crackers 200g | C23: =Base_Datos!C24 -> Alimentos Secos | D23: =Base_Datos!G24 -> 710 | E23: =Base_Datos!P24 -> 152.83333 | F23: =IFERROR(Base_Datos!G24/(Base_Datos!P24/30),9999) -> 139.3675 | G23: =IFERROR(Base_Datos!O24/Base_Datos!G24,0) -> 1.2915493 | H23: =Base_Datos!S24 -> 1242.5 | I23: =Base_Datos!H24 -> 39 | J23: =Base_Datos!R24 -> 26 | K23: =IF(IFERROR(Base_Datos!G24/(Base_Datos!P24/30),9999)<7,"🔴 QUIEBRE",IF(IFERROR(Base_Datos!G24/(Base_Datos!P24/30),9999)<14,"🟡 CRÍTICO",IF(IFERROR(Base_Datos!G24/(Base_Datos!P24/30),9999)<=90,"🟢 NORMAL",IF(IFERROR(Base_Datos!G24/(Base_Datos!P24/30),9999)<=180,"🟡 SOBRESTOCK","🔴 STOCK MUERTO")))) -> 🟡 SOBRESTOCK | L23: =IF(F23<7,"⚠ SÍ","—") -> — | M23: =IF(E23>=PERCENTILE($E$5:$E$79,0.8),"A",IF(E23>=PERCENTILE($E$5:$E$79,0.5),"B","C")) -> B | N23: =IFERROR(Base_Datos!O24/Base_Datos!O83,0) -> 0.018591732 | O23: =IF(F23<7,"REPOSICIÓN URGENTE",IF(F23<14,"Revisar orden de compra",IF(AND(F23>180,J23>60),"LIQUIDAR / DEVOLVER",IF(F23>90,"Reducir próxima compra","Stock en niveles óptimos")))) -> Reducir próxima compra | P23: =IF(F23<7,1,IF(AND(F23>180,J23>60),2,IF(F23<14,3,IF(F23>90,4,5)))) -> 4
A24: =Base_Datos!A25 -> SKU-020 | B24: =Base_Datos!B25 -> Puré de Tomate 520g | C24: =Base_Datos!C25 -> Alimentos Secos | D24: =Base_Datos!G25 -> 193 | E24: =Base_Datos!P25 -> 0.33333333 | F24: =IFERROR(Base_Datos!G25/(Base_Datos!P25/30),9999) -> 17370 | G24: =IFERROR(Base_Datos!O25/Base_Datos!G25,0) -> 0.010362694 | H24: =Base_Datos!S25 -> 250.9 | I24: =Base_Datos!H25 -> 5 | J24: =Base_Datos!R25 -> 92 | K24: =IF(IFERROR(Base_Datos!G25/(Base_Datos!P25/30),9999)<7,"🔴 QUIEBRE",IF(IFERROR(Base_Datos!G25/(Base_Datos!P25/30),9999)<14,"🟡 CRÍTICO",IF(IFERROR(Base_Datos!G25/(Base_Datos!P25/30),9999)<=90,"🟢 NORMAL",IF(IFERROR(Base_Datos!G25/(Base_Datos!P25/30),9999)<=180,"🟡 SOBRESTOCK","🔴 STOCK MUERTO")))) -> 🔴 STOCK MUERTO | L24: =IF(F24<7,"⚠ SÍ","—") -> — | M24: =IF(E24>=PERCENTILE($E$5:$E$79,0.8),"A",IF(E24>=PERCENTILE($E$5:$E$79,0.5),"B","C")) -> C | N24: =IFERROR(Base_Datos!O25/Base_Datos!O83,0) -> 4.0549034e-05 | O24: =IF(F24<7,"REPOSICIÓN URGENTE",IF(F24<14,"Revisar orden de compra",IF(AND(F24>180,J24>60),"LIQUIDAR / DEVOLVER",IF(F24>90,"Reducir próxima compra","Stock en niveles óptimos")))) -> LIQUIDAR / DEVOLVER | P24: =IF(F24<7,1,IF(AND(F24>180,J24>60),2,IF(F24<14,3,IF(F24>90,4,5)))) -> 2
A25: =Base_Datos!A26 -> SKU-021 | B25: =Base_Datos!B26 -> Tomate Triturado 400g | C25: =Base_Datos!C26 -> Alimentos Secos | D25: =Base_Datos!G26 -> 209 | E25: =Base_Datos!P26 -> 98.166667 | F25: =IFERROR(Base_Datos!G26/(Base_Datos!P26/30),9999) -> 63.870968 | G25: =IFERROR(Base_Datos!O26/Base_Datos!G26,0) -> 2.8181818 | H25: =Base_Datos!S26 -> 229.9 | I25: =Base_Datos!H26 -> 18 | J25: =Base_Datos!R26 -> 23 | K25: =IF(IFERROR(Base_Datos!G26/(Base_Datos!P26/30),9999)<7,"🔴 QUIEBRE",IF(IFERROR(Base_Datos!G26/(Base_Datos!P26/30),9999)<14,"🟡 CRÍTICO",IF(IFERROR(Base_Datos!G26/(Base_Datos!P26/30),9999)<=90,"🟢 NORMAL",IF(IFERROR(Base_Datos!G26/(Base_Datos!P26/30),9999)<=180,"🟡 SOBRESTOCK","🔴 STOCK MUERTO")))) -> 🟢 NORMAL | L25: =IF(F25<7,"⚠ SÍ","—") -> — | M25: =IF(E25>=PERCENTILE($E$5:$E$79,0.8),"A",IF(E25>=PERCENTILE($E$5:$E$79,0.5),"B","C")) -> B | N25: =IFERROR(Base_Datos!O26/Base_Datos!O83,0) -> 0.01194169 | O25: =IF(F25<7,"REPOSICIÓN URGENTE",IF(F25<14,"Revisar orden de compra",IF(AND(F25>180,J25>60),"LIQUIDAR / DEVOLVER",IF(F25>90,"Reducir próxima compra","Stock en niveles óptimos")))) -> Stock en niveles óptimos | P25: =IF(F25<7,1,IF(AND(F25>180,J25>60),2,IF(F25<14,3,IF(F25>90,4,5)))) -> 5
A26: =Base_Datos!A27 -> SKU-022 | B26: =Base_Datos!B27 -> Mayonesa 500g | C26: =Base_Datos!C27 -> Alimentos Secos | D26: =Base_Datos!G27 -> 25 | E26: =Base_Datos!P27 -> 406.83333 | F26: =IFERROR(Base_Datos!G27/(Base_Datos!P27/30),9999) -> 1.8435068 | G26: =IFERROR(Base_Datos!O27/Base_Datos!G27,0) -> 97.64 | H26: =Base_Datos!S27 -> 85 | I26: =Base_Datos!H27 -> 105 | J26: =Base_Datos!R27 -> 2 | K26: =IF(IFERROR(Base_Datos!G27/(Base_Datos!P27/30),9999)<7,"🔴 QUIEBRE",IF(IFERROR(Base_Datos!G27/(Base_Datos!P27/30),9999)<14,"🟡 CRÍTICO",IF(IFERROR(Base_Datos!G27/(Base_Datos!P27/30),9999)<=90,"🟢 NORMAL",IF(IFERROR(Base_Datos!G27/(Base_Datos!P27/30),9999)<=180,"🟡 SOBRESTOCK","🔴 STOCK MUERTO")))) -> 🔴 QUIEBRE | L26: =IF(F26<7,"⚠ SÍ","—") -> ⚠ SÍ | M26: =IF(E26>=PERCENTILE($E$5:$E$79,0.8),"A",IF(E26>=PERCENTILE($E$5:$E$79,0.5),"B","C")) -> A | N26: =IFERROR(Base_Datos!O27/Base_Datos!O83,0) -> 0.049490096 | O26: =IF(F26<7,"REPOSICIÓN URGENTE",IF(F26<14,"Revisar orden de compra",IF(AND(F26>180,J26>60),"LIQUIDAR / DEVOLVER",IF(F26>90,"Reducir próxima compra","Stock en niveles óptimos")))) -> REPOSICIÓN URGENTE | P26: =IF(F26<7,1,IF(AND(F26>180,J26>60),2,IF(F26<14,3,IF(F26>90,4,5)))) -> 1
A27: =Base_Datos!A28 -> SKU-023 | B27: =Base_Datos!B28 -> Ketchup 400g | C27: =Base_Datos!C28 -> Alimentos Secos | D27: =Base_Datos!G28 -> 115 | E27: =Base_Datos!P28 -> 123.83333 | F27: =IFERROR(Base_Datos!G28/(Base_Datos!P28/30),9999) -> 27.860027 | G27: =IFERROR(Base_Datos!O28/Base_Datos!G28,0) -> 6.4608696 | H27: =Base_Datos!S28 -> 322 | I27: =Base_Datos!H28 -> 22 | J27: =Base_Datos!R28 -> 20 | K27: =IF(IFERROR(Base_Datos!G28/(Base_Datos!P28/30),9999)<7,"🔴 QUIEBRE",IF(IFERROR(Base_Datos!G28/(Base_Datos!P28/30),9999)<14,"🟡 CRÍTICO",IF(IFERROR(Base_Datos!G28/(Base_Datos!P28/30),9999)<=90,"🟢 NORMAL",IF(IFERROR(Base_Datos!G28/(Base_Datos!P28/30),9999)<=180,"🟡 SOBRESTOCK","🔴 STOCK MUERTO")))) -> 🟢 NORMAL | L27: =IF(F27<7,"⚠ SÍ","—") -> — | M27: =IF(E27>=PERCENTILE($E$5:$E$79,0.8),"A",IF(E27>=PERCENTILE($E$5:$E$79,0.5),"B","C")) -> B | N27: =IFERROR(Base_Datos!O28/Base_Datos!O83,0) -> 0.015063966 | O27: =IF(F27<7,"REPOSICIÓN URGENTE",IF(F27<14,"Revisar orden de compra",IF(AND(F27>180,J27>60),"LIQUIDAR / DEVOLVER",IF(F27>90,"Reducir próxima compra","Stock en niveles óptimos")))) -> Stock en niveles óptimos | P27: =IF(F27<7,1,IF(AND(F27>180,J27>60),2,IF(F27<14,3,IF(F27>90,4,5)))) -> 5
A28: =Base_Datos!A29 -> SKU-024 | B28: =Base_Datos!B29 -> Lentejas 500g | C28: =Base_Datos!C29 -> Alimentos Secos | D28: =Base_Datos!G29 -> 12 | E28: =Base_Datos!P29 -> 6.5 | F28: =IFERROR(Base_Datos!G29/(Base_Datos!P29/30),9999) -> 55.384615 | G28: =IFERROR(Base_Datos!O29/Base_Datos!G29,0) -> 3.25 | H28: =Base_Datos!S29 -> 19.2 | I28: =Base_Datos!H29 -> 5 | J28: =Base_Datos!R29 -> 53 | K28: =IF(IFERROR(Base_Datos!G29/(Base_Datos!P29/30),9999)<7,"🔴 QUIEBRE",IF(IFERROR(Base_Datos!G29/(Base_Datos!P29/30),9999)<14,"🟡 CRÍTICO",IF(IFERROR(Base_Datos!G29/(Base_Datos!P29/30),9999)<=90,"🟢 NORMAL",IF(IFERROR(Base_Datos!G29/(Base_Datos!P29/30),9999)<=180,"🟡 SOBRESTOCK","🔴 STOCK MUERTO")))) -> 🟢 NORMAL | L28: =IF(F28<7,"⚠ SÍ","—") -> — | M28: =IF(E28>=PERCENTILE($E$5:$E$79,0.8),"A",IF(E28>=PERCENTILE($E$5:$E$79,0.5),"B","C")) -> C | N28: =IFERROR(Base_Datos!O29/Base_Datos!O83,0) -> 0.00079070616 | O28: =IF(F28<7,"REPOSICIÓN URGENTE",IF(F28<14,"Revisar orden de compra",IF(AND(F28>180,J28>60),"LIQUIDAR / DEVOLVER",IF(F28>90,"Reducir próxima compra","Stock en niveles óptimos")))) -> Stock en niveles óptimos | P28: =IF(F28<7,1,IF(AND(F28>180,J28>60),2,IF(F28<14,3,IF(F28>90,4,5)))) -> 5
A29: =Base_Datos!A30 -> SKU-025 | B29: =Base_Datos!B30 -> Porotos Negros 500g | C29: =Base_Datos!C30 -> Alimentos Secos | D29: =Base_Datos!G30 -> 304 | E29: =Base_Datos!P30 -> 160.33333 | F29: =IFERROR(Base_Datos!G30/(Base_Datos!P30/30),9999) -> 56.881497 | G29: =IFERROR(Base_Datos!O30/Base_Datos!G30,0) -> 3.1644737 | H29: =Base_Datos!S30 -> 516.8 | I29: =Base_Datos!H30 -> 35 | J29: =Base_Datos!R30 -> 30 | K29: =IF(IFERROR(Base_Datos!G30/(Base_Datos!P30/30),9999)<7,"🔴 QUIEBRE",IF(IFERROR(Base_Datos!G30/(Base_Datos!P30/30),9999)<14,"🟡 CRÍTICO",IF(IFERROR(Base_Datos!G30/(Base_Datos!P30/30),9999)<=90,"🟢 NORMAL",IF(IFERROR(Base_Datos!G30/(Base_Datos!P30/30),9999)<=180,"🟡 SOBRESTOCK","🔴 STOCK MUERTO")))) -> 🟢 NORMAL | L29: =IF(F29<7,"⚠ SÍ","—") -> — | M29: =IF(E29>=PERCENTILE($E$5:$E$79,0.8),"A",IF(E29>=PERCENTILE($E$5:$E$79,0.5),"B","C")) -> B | N29: =IFERROR(Base_Datos!O30/Base_Datos!O83,0) -> 0.019504085 | O29: =IF(F29<7,"REPOSICIÓN URGENTE",IF(F29<14,"Revisar orden de compra",IF(AND(F29>180,J29>60),"LIQUIDAR / DEVOLVER",IF(F29>90,"Reducir próxima compra","Stock en niveles óptimos")))) -> Stock en niveles óptimos | P29: =IF(F29<7,1,IF(AND(F29>180,J29>60),2,IF(F29<14,3,IF(F29>90,4,5)))) -> 5
A30: =Base_Datos!A32 -> SKU-026 | B30: =Base_Datos!B32 -> Lavandina Concentrada 1L | C30: =Base_Datos!C32 -> Limpieza del Hogar | D30: =Base_Datos!G32 -> 267 | E30: =Base_Datos!P32 -> 55.333333 | F30: =IFERROR(Base_Datos!G32/(Base_Datos!P32/30),9999) -> 144.75904 | G30: =IFERROR(Base_Datos!O32/Base_Datos!G32,0) -> 1.2434457 | H30: =Base_Datos!S32 -> 320.4 | I30: =Base_Datos!H32 -> 11 | J30: =Base_Datos!R32 -> 3 | K30: =IF(IFERROR(Base_Datos!G32/(Base_Datos!P32/30),9999)<7,"🔴 QUIEBRE",IF(IFERROR(Base_Datos!G32/(Base_Datos!P32/30),9999)<14,"🟡 CRÍTICO",IF(IFERROR(Base_Datos!G32/(Base_Datos!P32/30),9999)<=90,"🟢 NORMAL",IF(IFERROR(Base_Datos!G32/(Base_Datos!P32/30),9999)<=180,"🟡 SOBRESTOCK","🔴 STOCK MUERTO")))) -> 🟡 SOBRESTOCK | L30: =IF(F30<7,"⚠ SÍ","—") -> — | M30: =IF(E30>=PERCENTILE($E$5:$E$79,0.8),"A",IF(E30>=PERCENTILE($E$5:$E$79,0.5),"B","C")) -> C | N30: =IFERROR(Base_Datos!O32/Base_Datos!O83,0) -> 0.0067311396 | O30: =IF(F30<7,"REPOSICIÓN URGENTE",IF(F30<14,"Revisar orden de compra",IF(AND(F30>180,J30>60),"LIQUIDAR / DEVOLVER",IF(F30>90,"Reducir próxima compra","Stock en niveles óptimos")))) -> Reducir próxima compra | P30: =IF(F30<7,1,IF(AND(F30>180,J30>60),2,IF(F30<14,3,IF(F30>90,4,5)))) -> 4
A31: =Base_Datos!A33 -> SKU-027 | B31: =Base_Datos!B33 -> Lavandina Clásica 2L | C31: =Base_Datos!C33 -> Limpieza del Hogar | D31: =Base_Datos!G33 -> 210 | E31: =Base_Datos!P33 -> 110.16667 | F31: =IFERROR(Base_Datos!G33/(Base_Datos!P33/30),9999) -> 57.186082 | G31: =IFERROR(Base_Datos!O33/Base_Datos!G33,0) -> 3.147619 | H31: =Base_Datos!S33 -> 378 | I31: =Base_Datos!H33 -> 16 | J31: =Base_Datos!R33 -> 27 | K31: =IF(IFERROR(Base_Datos!G33/(Base_Datos!P33/30),9999)<7,"🔴 QUIEBRE",IF(IFERROR(Base_Datos!G33/(Base_Datos!P33/30),9999)<14,"🟡 CRÍTICO",IF(IFERROR(Base_Datos!G33/(Base_Datos!P33/30),9999)<=90,"🟢 NORMAL",IF(IFERROR(Base_Datos!G33/(Base_Datos!P33/30),9999)<=180,"🟡 SOBRESTOCK","🔴 STOCK MUERTO")))) -> 🟢 NORMAL | L31: =IF(F31<7,"⚠ SÍ","—") -> — | M31: =IF(E31>=PERCENTILE($E$5:$E$79,0.8),"A",IF(E31>=PERCENTILE($E$5:$E$79,0.5),"B","C")) -> B | N31: =IFERROR(Base_Datos!O33/Base_Datos!O83,0) -> 0.013401456 | O31: =IF(F31<7,"REPOSICIÓN URGENTE",IF(F31<14,"Revisar orden de compra",IF(AND(F31>180,J31>60),"LIQUIDAR / DEVOLVER",IF(F31>90,"Reducir próxima compra","Stock en niveles óptimos")))) -> Stock en niveles óptimos | P31: =IF(F31<7,1,IF(AND(F31>180,J31>60),2,IF(F31<14,3,IF(F31>90,4,5)))) -> 5
A32: =Base_Datos!A34 -> SKU-028 | B32: =Base_Datos!B34 -> Detergente Lavavajillas 500ml | C32: =Base_Datos!C34 -> Limpieza del Hogar | D32: =Base_Datos!G34 -> 135 | E32: =Base_Datos!P34 -> 127 | F32: =IFERROR(Base_Datos!G34/(Base_Datos!P34/30),9999) -> 31.889764 | G32: =IFERROR(Base_Datos!O34/Base_Datos!G34,0) -> 5.6444444 | H32: =Base_Datos!S34 -> 324 | I32: =Base_Datos!H34 -> 24 | J32: =Base_Datos!R34 -> 7 | K32: =IF(IFERROR(Base_Datos!G34/(Base_Datos!P34/30),9999)<7,"🔴 QUIEBRE",IF(IFERROR(Base_Datos!G34/(Base_Datos!P34/30),9999)<14,"🟡 CRÍTICO",IF(IFERROR(Base_Datos!G34/(Base_Datos!P34/30),9999)<=90,"🟢 NORMAL",IF(IFERROR(Base_Datos!G34/(Base_Datos!P34/30),9999)<=180,"🟡 SOBRESTOCK","🔴 STOCK MUERTO")))) -> 🟢 NORMAL | L32: =IF(F32<7,"⚠ SÍ","—") -> — | M32: =IF(E32>=PERCENTILE($E$5:$E$79,0.8),"A",IF(E32>=PERCENTILE($E$5:$E$79,0.5),"B","C")) -> B | N32: =IFERROR(Base_Datos!O34/Base_Datos!O83,0) -> 0.015449182 | O32: =IF(F32<7,"REPOSICIÓN URGENTE",IF(F32<14,"Revisar orden de compra",IF(AND(F32>180,J32>60),"LIQUIDAR / DEVOLVER",IF(F32>90,"Reducir próxima compra","Stock en niveles óptimos")))) -> Stock en niveles óptimos | P32: =IF(F32<7,1,IF(AND(F32>180,J32>60),2,IF(F32<14,3,IF(F32>90,4,5)))) -> 5
A33: =Base_Datos!A35 -> SKU-029 | B33: =Base_Datos!B35 -> Detergente Lavavajillas 1L | C33: =Base_Datos!C35 -> Limpieza del Hogar | D33: =Base_Datos!G35 -> 14 | E33: =Base_Datos!P35 -> 15.333333 | F33: =IFERROR(Base_Datos!G35/(Base_Datos!P35/30),9999) -> 27.391304 | G33: =IFERROR(Base_Datos!O35/Base_Datos!G35,0) -> 6.5714286 | H33: =Base_Datos!S35 -> 58.8 | I33: =Base_Datos!H35 -> 5 | J33: =Base_Datos!R35 -> 43 | K33: =IF(IFERROR(Base_Datos!G35/(Base_Datos!P35/30),9999)<7,"🔴 QUIEBRE",IF(IFERROR(Base_Datos!G35/(Base_Datos!P35/30),9999)<14,"🟡 CRÍTICO",IF(IFERROR(Base_Datos!G35/(Base_Datos!P35/30),9999)<=90,"🟢 NORMAL",IF(IFERROR(Base_Datos!G35/(Base_Datos!P35/30),9999)<=180,"🟡 SOBRESTOCK","🔴 STOCK MUERTO")))) -> 🟢 NORMAL | L33: =IF(F33<7,"⚠ SÍ","—") -> — | M33: =IF(E33>=PERCENTILE($E$5:$E$79,0.8),"A",IF(E33>=PERCENTILE($E$5:$E$79,0.5),"B","C")) -> C | N33: =IFERROR(Base_Datos!O35/Base_Datos!O83,0) -> 0.0018652556 | O33: =IF(F33<7,"REPOSICIÓN URGENTE",IF(F33<14,"Revisar orden de compra",IF(AND(F33>180,J33>60),"LIQUIDAR / DEVOLVER",IF(F33>90,"Reducir próxima compra","Stock en niveles óptimos")))) -> Stock en niveles óptimos | P33: =IF(F33<7,1,IF(AND(F33>180,J33>60),2,IF(F33<14,3,IF(F33>90,4,5)))) -> 5
A34: =Base_Datos!A36 -> SKU-030 | B34: =Base_Datos!B36 -> Jabón en Polvo 1kg | C34: =Base_Datos!C36 -> Limpieza del Hogar | D34: =Base_Datos!G36 -> 78 | E34: =Base_Datos!P36 -> 51.666667 | F34: =IFERROR(Base_Datos!G36/(Base_Datos!P36/30),9999) -> 45.290323 | G34: =IFERROR(Base_Datos!O36/Base_Datos!G36,0) -> 3.974359 | H34: =Base_Datos!S36 -> 374.4 | I34: =Base_Datos!H36 -> 7 | J34: =Base_Datos!R36 -> 3 | K34: =IF(IFERROR(Base_Datos!G36/(Base_Datos!P36/30),9999)<7,"🔴 QUIEBRE",IF(IFERROR(Base_Datos!G36/(Base_Datos!P36/30),9999)<14,"🟡 CRÍTICO",IF(IFERROR(Base_Datos!G36/(Base_Datos!P36/30),9999)<=90,"🟢 NORMAL",IF(IFERROR(Base_Datos!G36/(Base_Datos!P36/30),9999)<=180,"🟡 SOBRESTOCK","🔴 STOCK MUERTO")))) -> 🟢 NORMAL | L34: =IF(F34<7,"⚠ SÍ","—") -> — | M34: =IF(E34>=PERCENTILE($E$5:$E$79,0.8),"A",IF(E34>=PERCENTILE($E$5:$E$79,0.5),"B","C")) -> C | N34: =IFERROR(Base_Datos!O36/Base_Datos!O83,0) -> 0.0062851003 | O34: =IF(F34<7,"REPOSICIÓN URGENTE",IF(F34<14,"Revisar orden de compra",IF(AND(F34>180,J34>60),"LIQUIDAR / DEVOLVER",IF(F34>90,"Reducir próxima compra","Stock en niveles óptimos")))) -> Stock en niveles óptimos | P34: =IF(F34<7,1,IF(AND(F34>180,J34>60),2,IF(F34<14,3,IF(F34>90,4,5)))) -> 5
A35: =Base_Datos!A37 -> SKU-031 | B35: =Base_Datos!B37 -> Jabón en Polvo 3kg | C35: =Base_Datos!C37 -> Limpieza del Hogar | D35: =Base_Datos!G37 -> 512 | E35: =Base_Datos!P37 -> 76 | F35: =IFERROR(Base_Datos!G37/(Base_Datos!P37/30),9999) -> 202.10526 | G35: =IFERROR(Base_Datos!O37/Base_Datos!G37,0) -> 0.890625 | H35: =Base_Datos!S37 -> 6912 | I35: =Base_Datos!H37 -> 20 | J35: =Base_Datos!R37 -> 28 | K35: =IF(IFERROR(Base_Datos!G37/(Base_Datos!P37/30),9999)<7,"🔴 QUIEBRE",IF(IFERROR(Base_Datos!G37/(Base_Datos!P37/30),9999)<14,"🟡 CRÍTICO",IF(IFERROR(Base_Datos!G37/(Base_Datos!P37/30),9999)<=90,"🟢 NORMAL",IF(IFERROR(Base_Datos!G37/(Base_Datos!P37/30),9999)<=180,"🟡 SOBRESTOCK","🔴 STOCK MUERTO")))) -> 🔴 STOCK MUERTO | L35: =IF(F35<7,"⚠ SÍ","—") -> — | M35: =IF(E35>=PERCENTILE($E$5:$E$79,0.8),"A",IF(E35>=PERCENTILE($E$5:$E$79,0.5),"B","C")) -> C | N35: =IFERROR(Base_Datos!O37/Base_Datos!O83,0) -> 0.0092451797 | O35: =IF(F35<7,"REPOSICIÓN URGENTE",IF(F35<14,"Revisar orden de compra",IF(AND(F35>180,J35>60),"LIQUIDAR / DEVOLVER",IF(F35>90,"Reducir próxima compra","Stock en niveles óptimos")))) -> Reducir próxima compra | P35: =IF(F35<7,1,IF(AND(F35>180,J35>60),2,IF(F35<14,3,IF(F35>90,4,5)))) -> 4
A36: =Base_Datos!A38 -> SKU-032 | B36: =Base_Datos!B38 -> Suavizante Ropa 800ml | C36: =Base_Datos!C38 -> Limpieza del Hogar | D36: =Base_Datos!G38 -> 76 | E36: =Base_Datos!P38 -> 51.333333 | F36: =IFERROR(Base_Datos!G38/(Base_Datos!P38/30),9999) -> 44.415584 | G36: =IFERROR(Base_Datos!O38/Base_Datos!G38,0) -> 4.0526316 | H36: =Base_Datos!S38 -> 273.6 | I36: =Base_Datos!H38 -> 12 | J36: =Base_Datos!R38 -> 5 | K36: =IF(IFERROR(Base_Datos!G38/(Base_Datos!P38/30),9999)<7,"🔴 QUIEBRE",IF(IFERROR(Base_Datos!G38/(Base_Datos!P38/30),9999)<14,"🟡 CRÍTICO",IF(IFERROR(Base_Datos!G38/(Base_Datos!P38/30),9999)<=90,"🟢 NORMAL",IF(IFERROR(Base_Datos!G38/(Base_Datos!P38/30),9999)<=180,"🟡 SOBRESTOCK","🔴 STOCK MUERTO")))) -> 🟢 NORMAL | L36: =IF(F36<7,"⚠ SÍ","—") -> — | M36: =IF(E36>=PERCENTILE($E$5:$E$79,0.8),"A",IF(E36>=PERCENTILE($E$5:$E$79,0.5),"B","C")) -> C | N36: =IFERROR(Base_Datos!O38/Base_Datos!O83,0) -> 0.0062445512 | O36: =IF(F36<7,"REPOSICIÓN URGENTE",IF(F36<14,"Revisar orden de compra",IF(AND(F36>180,J36>60),"LIQUIDAR / DEVOLVER",IF(F36>90,"Reducir próxima compra","Stock en niveles óptimos")))) -> Stock en niveles óptimos | P36: =IF(F36<7,1,IF(AND(F36>180,J36>60),2,IF(F36<14,3,IF(F36>90,4,5)))) -> 5
A37: =Base_Datos!A39 -> SKU-033 | B37: =Base_Datos!B39 -> Suavizante Ropa 1.5L | C37: =Base_Datos!C39 -> Limpieza del Hogar | D37: =Base_Datos!G39 -> 185 | E37: =Base_Datos!P39 -> 1.1666667 | F37: =IFERROR(Base_Datos!G39/(Base_Datos!P39/30),9999) -> 4757.1429 | G37: =IFERROR(Base_Datos!O39/Base_Datos!G39,0) -> 0.037837838 | H37: =Base_Datos!S39 -> 1147 | I37: =Base_Datos!H39 -> 5 | J37: =Base_Datos!R39 -> 76 | K37: =IF(IFERROR(Base_Datos!G39/(Base_Datos!P39/30),9999)<7,"🔴 QUIEBRE",IF(IFERROR(Base_Datos!G39/(Base_Datos!P39/30),9999)<14,"🟡 CRÍTICO",IF(IFERROR(Base_Datos!G39/(Base_Datos!P39/30),9999)<=90,"🟢 NORMAL",IF(IFERROR(Base_Datos!G39/(Base_Datos!P39/30),9999)<=180,"🟡 SOBRESTOCK","🔴 STOCK MUERTO")))) -> 🔴 STOCK MUERTO | L37: =IF(F37<7,"⚠ SÍ","—") -> — | M37: =IF(E37>=PERCENTILE($E$5:$E$79,0.8),"A",IF(E37>=PERCENTILE($E$5:$E$79,0.5),"B","C")) -> C | N37: =IFERROR(Base_Datos!O39/Base_Datos!O83,0) -> 0.00014192162 | O37: =IF(F37<7,"REPOSICIÓN URGENTE",IF(F37<14,"Revisar orden de compra",IF(AND(F37>180,J37>60),"LIQUIDAR / DEVOLVER",IF(F37>90,"Reducir próxima compra","Stock en niveles óptimos")))) -> LIQUIDAR / DEVOLVER | P37: =IF(F37<7,1,IF(AND(F37>180,J37>60),2,IF(F37<14,3,IF(F37>90,4,5)))) -> 2
A38: =Base_Datos!A40 -> SKU-034 | B38: =Base_Datos!B40 -> Limpiador Multiuso 500ml | C38: =Base_Datos!C40 -> Limpieza del Hogar | D38: =Base_Datos!G40 -> 101 | E38: =Base_Datos!P40 -> 89.833333 | F38: =IFERROR(Base_Datos!G40/(Base_Datos!P40/30),9999) -> 33.729128 | G38: =IFERROR(Base_Datos!O40/Base_Datos!G40,0) -> 5.3366337 | H38: =Base_Datos!S40 -> 292.9 | I38: =Base_Datos!H40 -> 17 | J38: =Base_Datos!R40 -> 28 | K38: =IF(IFERROR(Base_Datos!G40/(Base_Datos!P40/30),9999)<7,"🔴 QUIEBRE",IF(IFERROR(Base_Datos!G40/(Base_Datos!P40/30),9999)<14,"🟡 CRÍTICO",IF(IFERROR(Base_Datos!G40/(Base_Datos!P40/30),9999)<=90,"🟢 NORMAL",IF(IFERROR(Base_Datos!G40/(Base_Datos!P40/30),9999)<=180,"🟡 SOBRESTOCK","🔴 STOCK MUERTO")))) -> 🟢 NORMAL | L38: =IF(F38<7,"⚠ SÍ","—") -> — | M38: =IF(E38>=PERCENTILE($E$5:$E$79,0.8),"A",IF(E38>=PERCENTILE($E$5:$E$79,0.5),"B","C")) -> C | N38: =IFERROR(Base_Datos!O40/Base_Datos!O83,0) -> 0.010927965 | O38: =IF(F38<7,"REPOSICIÓN URGENTE",IF(F38<14,"Revisar orden de compra",IF(AND(F38>180,J38>60),"LIQUIDAR / DEVOLVER",IF(F38>90,"Reducir próxima compra","Stock en niveles óptimos")))) -> Stock en niveles óptimos | P38: =IF(F38<7,1,IF(AND(F38>180,J38>60),2,IF(F38<14,3,IF(F38>90,4,5)))) -> 5
A39: =Base_Datos!A41 -> SKU-035 | B39: =Base_Datos!B41 -> Limpiador Piso 1L | C39: =Base_Datos!C41 -> Limpieza del Hogar | D39: =Base_Datos!G41 -> 43 | E39: =Base_Datos!P41 -> 183 | F39: =IFERROR(Base_Datos!G41/(Base_Datos!P41/30),9999) -> 7.0491803 | G39: =IFERROR(Base_Datos!O41/Base_Datos!G41,0) -> 25.534884 | H39: =Base_Datos!S41 -> 133.3 | I39: =Base_Datos!H41 -> 30 | J39: =Base_Datos!R41 -> 9 | K39: =IF(IFERROR(Base_Datos!G41/(Base_Datos!P41/30),9999)<7,"🔴 QUIEBRE",IF(IFERROR(Base_Datos!G41/(Base_Datos!P41/30),9999)<14,"🟡 CRÍTICO",IF(IFERROR(Base_Datos!G41/(Base_Datos!P41/30),9999)<=90,"🟢 NORMAL",IF(IFERROR(Base_Datos!G41/(Base_Datos!P41/30),9999)<=180,"🟡 SOBRESTOCK","🔴 STOCK MUERTO")))) -> 🟡 CRÍTICO | L39: =IF(F39<7,"⚠ SÍ","—") -> — | M39: =IF(E39>=PERCENTILE($E$5:$E$79,0.8),"A",IF(E39>=PERCENTILE($E$5:$E$79,0.5),"B","C")) -> A | N39: =IFERROR(Base_Datos!O41/Base_Datos!O83,0) -> 0.02226142 | O39: =IF(F39<7,"REPOSICIÓN URGENTE",IF(F39<14,"Revisar orden de compra",IF(AND(F39>180,J39>60),"LIQUIDAR / DEVOLVER",IF(F39>90,"Reducir próxima compra","Stock en niveles óptimos")))) -> Revisar orden de compra | P39: =IF(F39<7,1,IF(AND(F39>180,J39>60),2,IF(F39<14,3,IF(F39>90,4,5)))) -> 3
A40: =Base_Datos!A42 -> SKU-036 | B40: =Base_Datos!B42 -> Desengrasante 500ml | C40: =Base_Datos!C42 -> Limpieza del Hogar | D40: =Base_Datos!G42 -> 137 | E40: =Base_Datos!P42 -> 89 | F40: =IFERROR(Base_Datos!G42/(Base_Datos!P42/30),9999) -> 46.179775 | G40: =IFERROR(Base_Datos!O42/Base_Datos!G42,0) -> 3.8978102 | H40: =Base_Datos!S42 -> 479.5 | I40: =Base_Datos!H42 -> 26 | J40: =Base_Datos!R42 -> 4 | K40: =IF(IFERROR(Base_Datos!G42/(Base_Datos!P42/30),9999)<7,"🔴 QUIEBRE",IF(IFERROR(Base_Datos!G42/(Base_Datos!P42/30),9999)<14,"🟡 CRÍTICO",IF(IFERROR(Base_Datos!G42/(Base_Datos!P42/30),9999)<=90,"🟢 NORMAL",IF(IFERROR(Base_Datos!G42/(Base_Datos!P42/30),9999)<=180,"🟡 SOBRESTOCK","🔴 STOCK MUERTO")))) -> 🟢 NORMAL | L40: =IF(F40<7,"⚠ SÍ","—") -> — | M40: =IF(E40>=PERCENTILE($E$5:$E$79,0.8),"A",IF(E40>=PERCENTILE($E$5:$E$79,0.5),"B","C")) -> C | N40: =IFERROR(Base_Datos!O42/Base_Datos!O83,0) -> 0.010826592 | O40: =IF(F40<7,"REPOSICIÓN URGENTE",IF(F40<14,"Revisar orden de compra",IF(AND(F40>180,J40>60),"LIQUIDAR / DEVOLVER",IF(F40>90,"Reducir próxima compra","Stock en niveles óptimos")))) -> Stock en niveles óptimos | P40: =IF(F40<7,1,IF(AND(F40>180,J40>60),2,IF(F40<14,3,IF(F40>90,4,5)))) -> 5
A41: =Base_Datos!A43 -> SKU-037 | B41: =Base_Datos!B43 -> Limpiavidrios 500ml | C41: =Base_Datos!C43 -> Limpieza del Hogar | D41: =Base_Datos!G43 -> 274 | E41: =Base_Datos!P43 -> 139.33333 | F41: =IFERROR(Base_Datos!G43/(Base_Datos!P43/30),9999) -> 58.995215 | G41: =IFERROR(Base_Datos!O43/Base_Datos!G43,0) -> 3.0510949 | H41: =Base_Datos!S43 -> 739.8 | I41: =Base_Datos!H43 -> 40 | J41: =Base_Datos!R43 -> 24 | K41: =IF(IFERROR(Base_Datos!G43/(Base_Datos!P43/30),9999)<7,"🔴 QUIEBRE",IF(IFERROR(Base_Datos!G43/(Base_Datos!P43/30),9999)<14,"🟡 CRÍTICO",IF(IFERROR(Base_Datos!G43/(Base_Datos!P43/30),9999)<=90,"🟢 NORMAL",IF(IFERROR(Base_Datos!G43/(Base_Datos!P43/30),9999)<=180,"🟡 SOBRESTOCK","🔴 STOCK MUERTO")))) -> 🟢 NORMAL | L41: =IF(F41<7,"⚠ SÍ","—") -> — | M41: =IF(E41>=PERCENTILE($E$5:$E$79,0.8),"A",IF(E41>=PERCENTILE($E$5:$E$79,0.5),"B","C")) -> B | N41: =IFERROR(Base_Datos!O43/Base_Datos!O83,0) -> 0.016949496 | O41: =IF(F41<7,"REPOSICIÓN URGENTE",IF(F41<14,"Revisar orden de compra",IF(AND(F41>180,J41>60),"LIQUIDAR / DEVOLVER",IF(F41>90,"Reducir próxima compra","Stock en niveles óptimos")))) -> Stock en niveles óptimos | P41: =IF(F41<7,1,IF(AND(F41>180,J41>60),2,IF(F41<14,3,IF(F41>90,4,5)))) -> 5
...

Sheet Alertas
A1: PANEL DE ALERTAS OPERATIVAS
A2: Extracción automática de SKUs críticos · Actualización inmediata al cambiar Base_Datos · Usar para reuniones de operaciones
A4: 🔴 QUIEBRE INMINENTE — Cobertura menor a 7 días
A5: SKU ID | B5: Descripción | C5: Categoría | D5: Stock Actual | E5: Venta Prom. Mensual | F5: Días Cobertura | G5: Stock Mínimo | H5: ABC | I5: Capital Inmov. | J5: Acción
A6: =IFERROR(IF(Análisis!$K$5="🔴 QUIEBRE",Análisis!A5,""),"—") | B6: =IFERROR(IF(Análisis!$K$5="🔴 QUIEBRE",Análisis!B5,""),"—") | C6: =IFERROR(IF(Análisis!$K$5="🔴 QUIEBRE",Análisis!C5,""),"—") | D6: =IFERROR(IF(Análisis!$K$5="🔴 QUIEBRE",Análisis!D5,""),"—") | E6: =IFERROR(IF(Análisis!$K$5="🔴 QUIEBRE",Análisis!E5,""),"—") | F6: =IFERROR(IF(Análisis!$K$5="🔴 QUIEBRE",Análisis!F5,""),"—") | G6: =IFERROR(IF(Análisis!$K$5="🔴 QUIEBRE",Análisis!I5,""),"—") | H6: =IFERROR(IF(Análisis!$K$5="🔴 QUIEBRE",Análisis!M5,""),"—") | I6: =IFERROR(IF(Análisis!$K$5="🔴 QUIEBRE",Análisis!H5,""),"—") | J6: =IFERROR(IF(Análisis!$K$5="🔴 QUIEBRE",Análisis!O5,""),"—")
A7: =IFERROR(IF(Análisis!$K$6="🔴 QUIEBRE",Análisis!A6,""),"—") | B7: =IFERROR(IF(Análisis!$K$6="🔴 QUIEBRE",Análisis!B6,""),"—") | C7: =IFERROR(IF(Análisis!$K$6="🔴 QUIEBRE",Análisis!C6,""),"—") | D7: =IFERROR(IF(Análisis!$K$6="🔴 QUIEBRE",Análisis!D6,""),"—") | E7: =IFERROR(IF(Análisis!$K$6="🔴 QUIEBRE",Análisis!E6,""),"—") | F7: =IFERROR(IF(Análisis!$K$6="🔴 QUIEBRE",Análisis!F6,""),"—") | G7: =IFERROR(IF(Análisis!$K$6="🔴 QUIEBRE",Análisis!I6,""),"—") | H7: =IFERROR(IF(Análisis!$K$6="🔴 QUIEBRE",Análisis!M6,""),"—") | I7: =IFERROR(IF(Análisis!$K$6="🔴 QUIEBRE",Análisis!H6,""),"—") | J7: =IFERROR(IF(Análisis!$K$6="🔴 QUIEBRE",Análisis!O6,""),"—")
A8: =IFERROR(IF(Análisis!$K$7="🔴 QUIEBRE",Análisis!A7,""),"—") | B8: =IFERROR(IF(Análisis!$K$7="🔴 QUIEBRE",Análisis!B7,""),"—") | C8: =IFERROR(IF(Análisis!$K$7="🔴 QUIEBRE",Análisis!C7,""),"—") | D8: =IFERROR(IF(Análisis!$K$7="🔴 QUIEBRE",Análisis!D7,""),"—") | E8: =IFERROR(IF(Análisis!$K$7="🔴 QUIEBRE",Análisis!E7,""),"—") | F8: =IFERROR(IF(Análisis!$K$7="🔴 QUIEBRE",Análisis!F7,""),"—") | G8: =IFERROR(IF(Análisis!$K$7="🔴 QUIEBRE",Análisis!I7,""),"—") | H8: =IFERROR(IF(Análisis!$K$7="🔴 QUIEBRE",Análisis!M7,""),"—") | I8: =IFERROR(IF(Análisis!$K$7="🔴 QUIEBRE",Análisis!H7,""),"—") | J8: =IFERROR(IF(Análisis!$K$7="🔴 QUIEBRE",Análisis!O7,""),"—")
A9: =IFERROR(IF(Análisis!$K$8="🔴 QUIEBRE",Análisis!A8,""),"—") | B9: =IFERROR(IF(Análisis!$K$8="🔴 QUIEBRE",Análisis!B8,""),"—") | C9: =IFERROR(IF(Análisis!$K$8="🔴 QUIEBRE",Análisis!C8,""),"—") | D9: =IFERROR(IF(Análisis!$K$8="🔴 QUIEBRE",Análisis!D8,""),"—") | E9: =IFERROR(IF(Análisis!$K$8="🔴 QUIEBRE",Análisis!E8,""),"—") | F9: =IFERROR(IF(Análisis!$K$8="🔴 QUIEBRE",Análisis!F8,""),"—") | G9: =IFERROR(IF(Análisis!$K$8="🔴 QUIEBRE",Análisis!I8,""),"—") | H9: =IFERROR(IF(Análisis!$K$8="🔴 QUIEBRE",Análisis!M8,""),"—") | I9: =IFERROR(IF(Análisis!$K$8="🔴 QUIEBRE",Análisis!H8,""),"—") | J9: =IFERROR(IF(Análisis!$K$8="🔴 QUIEBRE",Análisis!O8,""),"—")
